[2019-03-26 19:23:21,151] {/home/alphatech/.local/lib/python3.6/site-packages/flask/app.py:1761} ERROR - Exception on /transaction [POST]
Traceback (most recent call last):
  File "/home/alphatech/.local/lib/python3.6/site-packages/flask/app.py", line 1813, in full_dispatch_request
    rv = self.dispatch_request()
  File "/home/alphatech/.local/lib/python3.6/site-packages/flask/app.py", line 1799, in dispatch_request
    return self.view_functions[rule.endpoint](**req.view_args)
  File "/home/alphatech/.local/lib/python3.6/site-packages/flask_restful/__init__.py", line 458, in wrapper
    resp = resource(*args, **kwargs)
  File "/home/alphatech/.local/lib/python3.6/site-packages/flask/views.py", line 88, in view
    return self.dispatch_request(*args, **kwargs)
  File "/home/alphatech/.local/lib/python3.6/site-packages/flask_restful/__init__.py", line 573, in dispatch_request
    resp = meth(*args, **kwargs)
  File "/home/alphatech/.local/lib/python3.6/site-packages/flask_jwt_extended/view_decorators.py", line 104, in wrapper
    return fn(*args, **kwargs)
  File "/home/alphatech/Documents/BIG/Fase awal/env_eCommerce/eCommerce/blueprints/transaction/resources.py", line 113, in post
    db.session.commit()
  File "/home/alphatech/.local/lib/python3.6/site-packages/sqlalchemy/orm/scoping.py", line 162, in do
    return getattr(self.registry(), name)(*args, **kwargs)
  File "/home/alphatech/.local/lib/python3.6/site-packages/sqlalchemy/orm/session.py", line 1026, in commit
    self.transaction.commit()
  File "/home/alphatech/.local/lib/python3.6/site-packages/sqlalchemy/orm/session.py", line 493, in commit
    self._prepare_impl()
  File "/home/alphatech/.local/lib/python3.6/site-packages/sqlalchemy/orm/session.py", line 472, in _prepare_impl
    self.session.flush()
  File "/home/alphatech/.local/lib/python3.6/site-packages/sqlalchemy/orm/session.py", line 2451, in flush
    self._flush(objects)
  File "/home/alphatech/.local/lib/python3.6/site-packages/sqlalchemy/orm/session.py", line 2589, in _flush
    transaction.rollback(_capture_exception=True)
  File "/home/alphatech/.local/lib/python3.6/site-packages/sqlalchemy/util/langhelpers.py", line 68, in __exit__
    compat.reraise(exc_type, exc_value, exc_tb)
  File "/home/alphatech/.local/lib/python3.6/site-packages/sqlalchemy/util/compat.py", line 129, in reraise
    raise value
  File "/home/alphatech/.local/lib/python3.6/site-packages/sqlalchemy/orm/session.py", line 2549, in _flush
    flush_context.execute()
  File "/home/alphatech/.local/lib/python3.6/site-packages/sqlalchemy/orm/unitofwork.py", line 422, in execute
    rec.execute(self)
  File "/home/alphatech/.local/lib/python3.6/site-packages/sqlalchemy/orm/unitofwork.py", line 589, in execute
    uow,
  File "/home/alphatech/.local/lib/python3.6/site-packages/sqlalchemy/orm/persistence.py", line 213, in save_obj
    ) in _organize_states_for_save(base_mapper, states, uowtransaction):
  File "/home/alphatech/.local/lib/python3.6/site-packages/sqlalchemy/orm/persistence.py", line 408, in _organize_states_for_save
    % (state_str(state), instance_key, state_str(existing))
sqlalchemy.orm.exc.FlushError: New instance <Transactions at 0x7fd64365aa20> with identity key (<class 'blueprints.transaction.Transactions'>, (10,), None) conflicts with persistent instance <Transactions at 0x7fd642015390>
[2019-03-26 19:23:25,322] {/home/alphatech/.local/lib/python3.6/site-packages/flask/app.py:1761} ERROR - Exception on /transaction [POST]
Traceback (most recent call last):
  File "/home/alphatech/.local/lib/python3.6/site-packages/flask/app.py", line 1813, in full_dispatch_request
    rv = self.dispatch_request()
  File "/home/alphatech/.local/lib/python3.6/site-packages/flask/app.py", line 1799, in dispatch_request
    return self.view_functions[rule.endpoint](**req.view_args)
  File "/home/alphatech/.local/lib/python3.6/site-packages/flask_restful/__init__.py", line 458, in wrapper
    resp = resource(*args, **kwargs)
  File "/home/alphatech/.local/lib/python3.6/site-packages/flask/views.py", line 88, in view
    return self.dispatch_request(*args, **kwargs)
  File "/home/alphatech/.local/lib/python3.6/site-packages/flask_restful/__init__.py", line 573, in dispatch_request
    resp = meth(*args, **kwargs)
  File "/home/alphatech/.local/lib/python3.6/site-packages/flask_jwt_extended/view_decorators.py", line 104, in wrapper
    return fn(*args, **kwargs)
  File "/home/alphatech/Documents/BIG/Fase awal/env_eCommerce/eCommerce/blueprints/transaction/resources.py", line 113, in post
    db.session.commit()
  File "/home/alphatech/.local/lib/python3.6/site-packages/sqlalchemy/orm/scoping.py", line 162, in do
    return getattr(self.registry(), name)(*args, **kwargs)
  File "/home/alphatech/.local/lib/python3.6/site-packages/sqlalchemy/orm/session.py", line 1026, in commit
    self.transaction.commit()
  File "/home/alphatech/.local/lib/python3.6/site-packages/sqlalchemy/orm/session.py", line 493, in commit
    self._prepare_impl()
  File "/home/alphatech/.local/lib/python3.6/site-packages/sqlalchemy/orm/session.py", line 472, in _prepare_impl
    self.session.flush()
  File "/home/alphatech/.local/lib/python3.6/site-packages/sqlalchemy/orm/session.py", line 2451, in flush
    self._flush(objects)
  File "/home/alphatech/.local/lib/python3.6/site-packages/sqlalchemy/orm/session.py", line 2589, in _flush
    transaction.rollback(_capture_exception=True)
  File "/home/alphatech/.local/lib/python3.6/site-packages/sqlalchemy/util/langhelpers.py", line 68, in __exit__
    compat.reraise(exc_type, exc_value, exc_tb)
  File "/home/alphatech/.local/lib/python3.6/site-packages/sqlalchemy/util/compat.py", line 129, in reraise
    raise value
  File "/home/alphatech/.local/lib/python3.6/site-packages/sqlalchemy/orm/session.py", line 2549, in _flush
    flush_context.execute()
  File "/home/alphatech/.local/lib/python3.6/site-packages/sqlalchemy/orm/unitofwork.py", line 422, in execute
    rec.execute(self)
  File "/home/alphatech/.local/lib/python3.6/site-packages/sqlalchemy/orm/unitofwork.py", line 589, in execute
    uow,
  File "/home/alphatech/.local/lib/python3.6/site-packages/sqlalchemy/orm/persistence.py", line 213, in save_obj
    ) in _organize_states_for_save(base_mapper, states, uowtransaction):
  File "/home/alphatech/.local/lib/python3.6/site-packages/sqlalchemy/orm/persistence.py", line 408, in _organize_states_for_save
    % (state_str(state), instance_key, state_str(existing))
sqlalchemy.orm.exc.FlushError: New instance <Transactions at 0x7fd641ffd400> with identity key (<class 'blueprints.transaction.Transactions'>, (10,), None) conflicts with persistent instance <Transactions at 0x7fd642a9e0b8>
