[2019-03-23 16:11:51,541] {/home/alphatech/.local/lib/python3.6/site-packages/flask/app.py:1761} ERROR - Exception on /auth [OPTIONS]
Traceback (most recent call last):
  File "/home/alphatech/.local/lib/python3.6/site-packages/flask/app.py", line 2292, in wsgi_app
    response = self.full_dispatch_request()
  File "/home/alphatech/.local/lib/python3.6/site-packages/flask/app.py", line 1816, in full_dispatch_request
    return self.finalize_request(rv)
  File "/home/alphatech/.local/lib/python3.6/site-packages/flask/app.py", line 1833, in finalize_request
    response = self.process_response(response)
  File "/home/alphatech/.local/lib/python3.6/site-packages/flask/app.py", line 2112, in process_response
    response = handler(response)
  File "/home/alphatech/Documents/BIG/Fase awal/env_eCommerce/eCommerce/blueprints/__init__.py", line 38, in after_request
    app.logger.warning("REQUEST_LOG\t%s %s", json.dumps, request.method, request.url, ({ 'request': request.get_json(), 'response': json.loads(response.data.decode('utf-8')) }))
  File "/usr/lib/python3.6/json/__init__.py", line 354, in loads
    return _default_decoder.decode(s)
  File "/usr/lib/python3.6/json/decoder.py", line 339, in decode
    obj, end = self.raw_decode(s, idx=_w(s, 0).end())
  File "/usr/lib/python3.6/json/decoder.py", line 357, in raw_decode
    raise JSONDecodeError("Expecting value", s, err.value) from None
json.decoder.JSONDecodeError: Expecting value: line 1 column 1 (char 0)
[2019-03-23 16:12:56,023] {/home/alphatech/.local/lib/python3.6/site-packages/flask/app.py:1761} ERROR - Exception on /auth [OPTIONS]
Traceback (most recent call last):
  File "/home/alphatech/.local/lib/python3.6/site-packages/flask/app.py", line 2292, in wsgi_app
    response = self.full_dispatch_request()
  File "/home/alphatech/.local/lib/python3.6/site-packages/flask/app.py", line 1816, in full_dispatch_request
    return self.finalize_request(rv)
  File "/home/alphatech/.local/lib/python3.6/site-packages/flask/app.py", line 1833, in finalize_request
    response = self.process_response(response)
  File "/home/alphatech/.local/lib/python3.6/site-packages/flask/app.py", line 2112, in process_response
    response = handler(response)
  File "/home/alphatech/Documents/BIG/Fase awal/env_eCommerce/eCommerce/blueprints/__init__.py", line 38, in after_request
    app.logger.warning("REQUEST_LOG\t%s %s", json.dumps, request.method, request.url, ({ 'request': request.get_json(), 'response': json.loads(response.data.decode('utf-8')) }))
  File "/usr/lib/python3.6/json/__init__.py", line 354, in loads
    return _default_decoder.decode(s)
  File "/usr/lib/python3.6/json/decoder.py", line 339, in decode
    obj, end = self.raw_decode(s, idx=_w(s, 0).end())
  File "/usr/lib/python3.6/json/decoder.py", line 357, in raw_decode
    raise JSONDecodeError("Expecting value", s, err.value) from None
json.decoder.JSONDecodeError: Expecting value: line 1 column 1 (char 0)
[2019-03-23 16:14:48,158] {/home/alphatech/.local/lib/python3.6/site-packages/flask/app.py:1761} ERROR - Exception on /auth [OPTIONS]
Traceback (most recent call last):
  File "/home/alphatech/.local/lib/python3.6/site-packages/flask/app.py", line 2292, in wsgi_app
    response = self.full_dispatch_request()
  File "/home/alphatech/.local/lib/python3.6/site-packages/flask/app.py", line 1816, in full_dispatch_request
    return self.finalize_request(rv)
  File "/home/alphatech/.local/lib/python3.6/site-packages/flask/app.py", line 1833, in finalize_request
    response = self.process_response(response)
  File "/home/alphatech/.local/lib/python3.6/site-packages/flask/app.py", line 2112, in process_response
    response = handler(response)
  File "/home/alphatech/Documents/BIG/Fase awal/env_eCommerce/eCommerce/blueprints/__init__.py", line 38, in after_request
    app.logger.warning("REQUEST_LOG\t%s %s", json.dumps, request.method, request.url, ({ 'request': request.get_json(), 'response': json.loads(response.data.decode('utf-8')) }))
  File "/usr/lib/python3.6/json/__init__.py", line 354, in loads
    return _default_decoder.decode(s)
  File "/usr/lib/python3.6/json/decoder.py", line 339, in decode
    obj, end = self.raw_decode(s, idx=_w(s, 0).end())
  File "/usr/lib/python3.6/json/decoder.py", line 357, in raw_decode
    raise JSONDecodeError("Expecting value", s, err.value) from None
json.decoder.JSONDecodeError: Expecting value: line 1 column 1 (char 0)
[2019-03-23 16:16:23,677] {/home/alphatech/.local/lib/python3.6/site-packages/flask/app.py:1761} ERROR - Exception on /auth [OPTIONS]
Traceback (most recent call last):
  File "/home/alphatech/.local/lib/python3.6/site-packages/flask/app.py", line 2292, in wsgi_app
    response = self.full_dispatch_request()
  File "/home/alphatech/.local/lib/python3.6/site-packages/flask/app.py", line 1816, in full_dispatch_request
    return self.finalize_request(rv)
  File "/home/alphatech/.local/lib/python3.6/site-packages/flask/app.py", line 1833, in finalize_request
    response = self.process_response(response)
  File "/home/alphatech/.local/lib/python3.6/site-packages/flask/app.py", line 2112, in process_response
    response = handler(response)
  File "/home/alphatech/Documents/BIG/Fase awal/env_eCommerce/eCommerce/blueprints/__init__.py", line 38, in after_request
    app.logger.warning("REQUEST_LOG\t%s %s", json.dumps, request.method, request.url, ({ 'request': request.get_json(), 'response': json.loads(response.data.decode('utf-8')) }))
  File "/usr/lib/python3.6/json/__init__.py", line 354, in loads
    return _default_decoder.decode(s)
  File "/usr/lib/python3.6/json/decoder.py", line 339, in decode
    obj, end = self.raw_decode(s, idx=_w(s, 0).end())
  File "/usr/lib/python3.6/json/decoder.py", line 357, in raw_decode
    raise JSONDecodeError("Expecting value", s, err.value) from None
json.decoder.JSONDecodeError: Expecting value: line 1 column 1 (char 0)
[2019-03-23 16:17:21,855] {/home/alphatech/.local/lib/python3.6/site-packages/flask/app.py:1761} ERROR - Exception on /auth [OPTIONS]
Traceback (most recent call last):
  File "/home/alphatech/.local/lib/python3.6/site-packages/flask/app.py", line 2292, in wsgi_app
    response = self.full_dispatch_request()
  File "/home/alphatech/.local/lib/python3.6/site-packages/flask/app.py", line 1816, in full_dispatch_request
    return self.finalize_request(rv)
  File "/home/alphatech/.local/lib/python3.6/site-packages/flask/app.py", line 1833, in finalize_request
    response = self.process_response(response)
  File "/home/alphatech/.local/lib/python3.6/site-packages/flask/app.py", line 2112, in process_response
    response = handler(response)
  File "/home/alphatech/Documents/BIG/Fase awal/env_eCommerce/eCommerce/blueprints/__init__.py", line 38, in after_request
    app.logger.warning("REQUEST_LOG\t%s %s", json.dumps, request.method, request.url, ({ 'request': request.get_json(), 'response': json.loads(response.data.decode('utf-8')) }))
  File "/usr/lib/python3.6/json/__init__.py", line 354, in loads
    return _default_decoder.decode(s)
  File "/usr/lib/python3.6/json/decoder.py", line 339, in decode
    obj, end = self.raw_decode(s, idx=_w(s, 0).end())
  File "/usr/lib/python3.6/json/decoder.py", line 357, in raw_decode
    raise JSONDecodeError("Expecting value", s, err.value) from None
json.decoder.JSONDecodeError: Expecting value: line 1 column 1 (char 0)
[2019-03-23 16:19:53,436] {/home/alphatech/.local/lib/python3.6/site-packages/flask/app.py:1761} ERROR - Exception on /auth [OPTIONS]
Traceback (most recent call last):
  File "/home/alphatech/.local/lib/python3.6/site-packages/flask/app.py", line 2292, in wsgi_app
    response = self.full_dispatch_request()
  File "/home/alphatech/.local/lib/python3.6/site-packages/flask/app.py", line 1816, in full_dispatch_request
    return self.finalize_request(rv)
  File "/home/alphatech/.local/lib/python3.6/site-packages/flask/app.py", line 1833, in finalize_request
    response = self.process_response(response)
  File "/home/alphatech/.local/lib/python3.6/site-packages/flask/app.py", line 2112, in process_response
    response = handler(response)
  File "/home/alphatech/Documents/BIG/Fase awal/env_eCommerce/eCommerce/blueprints/__init__.py", line 38, in after_request
    app.logger.warning("REQUEST_LOG\t%s %s", json.dumps, request.method, request.url, ({ 'request': request.get_json(), 'response': json.loads(response.data.decode('utf-8')) }))
  File "/usr/lib/python3.6/json/__init__.py", line 354, in loads
    return _default_decoder.decode(s)
  File "/usr/lib/python3.6/json/decoder.py", line 339, in decode
    obj, end = self.raw_decode(s, idx=_w(s, 0).end())
  File "/usr/lib/python3.6/json/decoder.py", line 357, in raw_decode
    raise JSONDecodeError("Expecting value", s, err.value) from None
json.decoder.JSONDecodeError: Expecting value: line 1 column 1 (char 0)
